Workbook
Name Name: 'Client Data'!$A:$A

Sheet Client Data
A1: Client Details
A3: Name | B3: CLIENT_NAME
A4: email | B4: CLIENT_EMAIL
A5: phone | B5: CLIENT_PHONE
A6: Address 1 | B6: CLIENT_ADDRESS1
A7: Address 2 | B7: CLIENT_ADDRESS2
A8: Address 3 | B8: CLIENT_ADDRESS3
A9: Town | B9: CLIENT_TOWN
A10: Postcode | B10: CLIENT_POSTCODE
A12: Event Details
A13: Type | B13: EVENT_TYPE
A14: Date | B14: EVENT_DATE
A15: Start | B15: EVENT_START
A16: End | B16: EVENT_END
A18: Venue Details
A19: Name | B19: VENUE_NAME
A20: Address 1 | B20: VENUE_ADDRESS1
A21: Address 2 | B21: VENUE_ADDRESS2
A22: Address 3 | B22: VENUE_ADDRESS3
A23: Town | B23: VENUE_TOWN
A24: Postcode | B24: VENUE_POSTCODE
A26: Billing Details
A27: AhMen fee | B27: AHMEN_FEE
A28: Specialist singers / other fees | B28: EXTRA_FEES
A29: Sound/AV or production | B29: PRODUCTION_FEES
A30: Total fees | B30: TOTAL_FEES
A31: Deposit | B31: DEPOSIT_AMOUNT
A32: Balance | B32: BALANCE_AMOUNT
A33: Balance due | B33: BALANCE_DATE
A34: balance reminder date | B34: BALANCE_REMIND
A36: Services
A37: Type(s) | B37: SERVICE_TYPE
A38: Specialist singers | B38: SPECIALIST_SINGERS

Sheet Quote
B2: QUOTE
B5: Client: | E5: Quote Date:
B6: ='Client Data'!B3 -> CLIENT_NAME | E6: =TODAY() -> 45925
B7: ='Client Data'!B4 -> CLIENT_EMAIL | H7: AhMen a cappella Ltd
B8: ='Client Data'!B5 -> CLIENT_PHONE | E8: Reference: | H8: 2 Alloa Court,
B9: =IF('Client Data'!B6<>"",'Client Data'!B6,"") -> CLIENT_ADDRESS1 | E9: ='Client Data'!B3 -> CLIENT_NAME | H9: 139 Ashfield Road,
B10: =IF('Client Data'!B7<>"",'Client Data'!B7,"") -> CLIENT_ADDRESS2 | E10: ='Client Data'!B14 -> EVENT_DATE | H10: London N14 7PE,
B11: =IF('Client Data'!B8<>"",'Client Data'!B8,"") -> CLIENT_ADDRESS3 | H11: UNITED KINGDOM
B12: =IF('Client Data'!B9<>"",'Client Data'!B9,"") -> CLIENT_TOWN
B13: =IF('Client Data'!B10<>"",'Client Data'!B10,"") -> CLIENT_POSTCODE
B20: Description | E20: Venue | F20: Fee | I20: Payable
B21: AhMen performance | E21: ='Client Data'!B19 -> VENUE_NAME | F21: ='Client Data'!B27 -> AHMEN_FEE
B22: Specialist singers / other fees | F22: ='Client Data'!B28 -> EXTRA_FEES
B23: Sound/AV/production | F23: ='Client Data'!B29 -> PRODUCTION_FEES
B25: Deposit (30%) to secure booking | I25: ='Client Data'!B31 -> DEPOSIT_AMOUNT
B26: Balance payment (70%) due 10 days before event | I26: ='Client Data'!B32 -> BALANCE_AMOUNT
F29: Subtotal | I29: =SUM(I21:I28) -> 0
F30: VAT | I30: 0
F31: TOTAL | I31: =SUM(I29:I30) -> 0

Sheet Booking Schedule
B2: BOOKING SCHEDULE
H7: AhMen a cappella Ltd
H8: 2 Alloa Court,
H9: 139 Ashfield Road,
H10: London N14 7PE,
H11: UNITED KINGDOM
B14: A) Client & Event
B16: Client Name: | D16: ='Client Data'!B3 -> CLIENT_NAME
B17: Email: | D17: ='Client Data'!B4 -> CLIENT_EMAIL
B18: Mobile: | D18: ='Client Data'!B5 -> CLIENT_PHONE
B19: Event Date: | D19: ='Client Data'!B14 -> EVENT_DATE
B20: Venue (Name & Address): | D20: ='Client Data'!B19 -> VENUE_NAME
D21: =IF('Client Data'!B20<>"",'Client Data'!B20,"") -> VENUE_ADDRESS1
D22: =IF('Client Data'!B21<>"",'Client Data'!B21,"") -> VENUE_ADDRESS2
D23: =IF('Client Data'!B23<>"",'Client Data'!B23,"") -> VENUE_TOWN
D24: =IF('Client Data'!B24<>"",'Client Data'!B24,"") -> VENUE_POSTCODE
B25: Event Start: | D25: ='Client Data'!B15 -> EVENT_START
B26: Event End: | D26: ='Client Data'!B16 -> EVENT_END
B27: Event Type / Occasion: | D27: ='Client Data'!B13 -> EVENT_TYPE
B30: B) Services
B32: Service Type(s): | D32: ='Client Data'!B37 -> SERVICE_TYPE
B33: Specialised Singer(s): | D33: ='Client Data'!B38 -> SPECIALIST_SINGERS
B34: Sound/AV (if required): | D34: ☐ AhMen to provide Sound/AV
B35: Additional Production (staging/lighting/etc.):
B39: C) Facilities & Catering
B41: Private Room for changing/refreshing/rehearsing — Confirmed | G41: ☐
B42: Meals provided for each performer/staff — Confirmed | G42: ☐
B43: Caterer (Company/Name):
B44: Special Requirements (incl. dietary):
B45: we’ll notify you in advance; client will cater and/or cover the cost — Confirmed | G45: ☐
B47: D) Fees & Payment
B49: AhMen Fee (AhMen performance fee, excluding add-ons): | F49: ='Client Data'!B27 -> AHMEN_FEE
B50: Add-on Fee(s) (if applicable): | F50: ='Client Data'!B28 -> EXTRA_FEES
B51: Production Fee(s) (if applicable): | F51: ='Client Data'!B29 -> PRODUCTION_FEES
B52: Total Fee | F52: ='Client Data'!B30 -> TOTAL_FEES
B53: Deposit (30%) — due on signing: | F53: ='Client Data'!B31 -> DEPOSIT_AMOUNT
B54: Balance (70%) — due no later than 10 days before Event Date: | F54: ='Client Data'!B32 -> BALANCE_AMOUNT
B55: Travel & Parking (client to cover; recharged at cost) — Confirmed | G55: ☐
B56: Accommodation (if applicable; client to cover; recharged at cost) — Confirmed | G56: ☐
B57: Payment Method: Bank transfer (unless otherwise agreed)
...

Sheet T&Cs
B2: BOOKING TERMS & CONDITIONS
B7: Who we are / who you are
B8: This booking is between AhMen a cappella Ltd (“we/us”) and the Client (“you”) named on the Booking
B9: Schedule.
B10: 1) Making it official
B11: • The booking becomes binding when we receive your signature + 30% deposit.
B12: • Please do both within 10 days of the date we send the agreement (bank clearing time included). If not, we may
B13: release the date.
B14: 2) Payments
B15: • Deposit: 30% on signing (non-refundable).
B16: • Balance: 70% no later than 10 days before the Event Date (cleared funds).
B17: • If anything’s unpaid, we may pause/not perform until paid.
... B71: Technical Rider, and any Special Conditions / Agreed Variations relating to this booking.

Sheet Invoice - deposit
B2: INVOICE
B5: Invoice To: | E5: Invoice Date:
B6: ='Client Data'!B3 -> CLIENT_NAME | E6: =TODAY() -> 45925
B7: ='Client Data'!B4 -> CLIENT_EMAIL | H7: AhMen a cappella Ltd
B8: ='Client Data'!B5 -> CLIENT_PHONE | E8: Invoice Number: | H8: 2 Alloa Court,
B9: =IF('Client Data'!B6<>"",'Client Data'!B6,"") -> CLIENT_ADDRESS1 | E9: INV- | H9: 139 Ashfield Road,
B10: =IF('Client Data'!B7<>"",'Client Data'!B7,"") -> CLIENT_ADDRESS2 | H10: London N14 7PE,
B11: =IF('Client Data'!B8<>"",'Client Data'!B8,"") -> CLIENT_ADDRESS3 | E11: Reference: | H11: UNITED KINGDOM
B12: =IF('Client Data'!B9<>"",'Client Data'!B9,"") -> CLIENT_TOWN | E12: =B6 -> CLIENT_NAME
B13: =IF('Client Data'!B10<>"",'Client Data'!B10,"") -> CLIENT_POSTCODE | E13: ='Client Data'!$B$14 -> EVENT_DATE
B20: Description | E20: Venue | F20: Fee | I20: Payable
B21: AhMen performance | E21: ='Client Data'!B19 -> VENUE_NAME | F21: ='Client Data'!B27 -> AHMEN_FEE
B22: Specialist singers / other fees | F22: ='Client Data'!B28 -> EXTRA_FEES
B23: Sound/AV/production | F23: ='Client Data'!B29 -> PRODUCTION_FEES
B26: Deposit (30%) | I26: ='Client Data'!B31 -> DEPOSIT_AMOUNT
F29: Subtotal | I29: =SUM(I21:I28) -> 0
F30: VAT | I30: 0
F31: TOTAL | I31: =SUM(I29:I30) -> 0
B33: Due Date: | C33: =TODAY() -> 45925
B35: BACS Payments to:
B36: Barclays Bank
B37: Sort Code 20 - 45 - 45
B38: Acc No. 43781046
B39: Acc name: AHMEN a cappella Ltd

Sheet Invoice - balance
B2: INVOICE
B5: Invoice To: | E5: Invoice Date:
B6: ='Client Data'!B3 -> CLIENT_NAME | E6: =E13-20 -> #VALUE!
B7: ='Client Data'!B4 -> CLIENT_EMAIL | H7: AhMen a cappella Ltd
B8: ='Client Data'!B5 -> CLIENT_PHONE | E8: Invoice Number: | H8: 2 Alloa Court,
B9: =IF('Client Data'!B6<>"",'Client Data'!B6,"") -> CLIENT_ADDRESS1 | E9: INV- | H9: 139 Ashfield Road,
B10: =IF('Client Data'!B7<>"",'Client Data'!B7,"") -> CLIENT_ADDRESS2 | H10: London N14 7PE,
B11: =IF('Client Data'!B8<>"",'Client Data'!B8,"") -> CLIENT_ADDRESS3 | E11: Reference: | H11: UNITED KINGDOM
B12: =IF('Client Data'!B9<>"",'Client Data'!B9,"") -> CLIENT_TOWN | E12: =B6 -> CLIENT_NAME
B13: =IF('Client Data'!B10<>"",'Client Data'!B10,"") -> CLIENT_POSTCODE | E13: ='Client Data'!$B$14 -> EVENT_DATE
B20: Description | E20: Venue | F20: Fee | I20: Payable
B21: AhMen performance | E21: ='Client Data'!B19 -> VENUE_NAME | F21: ='Client Data'!B27 -> AHMEN_FEE
B22: Specialist singers / other fees | F22: ='Client Data'!B28 -> EXTRA_FEES
B23: Sound/AV/production | F23: ='Client Data'!B29 -> PRODUCTION_FEES
B26: Balance payment (70%) | I26: ='Client Data'!B32 -> BALANCE_AMOUNT
F29: Subtotal | I29: =SUM(I21:I28) -> 0
F30: VAT | I30: 0
F31: TOTAL | I31: =SUM(I29:I30) -> 0
B33: Due Date: | C33: =E13-10 -> #VALUE!
B35: BACS Payments to:
B36: Barclays Bank
B37: Sort Code 20 - 45 - 45
B38: Acc No. 43781046
B39: Acc name: AHMEN a cappella Ltd
